<robot
  name="broom">
  <link
    name="broom_foot">
    <inertial>
      <origin
        xyz="2.6394E-08 -0.43128 -2.2446E-08"
        rpy="0 0 0" />
      <mass
        value="0.27406" />
      <inertia
        ixx="0.016374"
        ixy="-2.6073E-09"
        ixz="2.7007E-11"
        iyy="1.5214E-05"
        iyz="-7.2588E-11"
        izz="0.016375" />
    </inertial>
    <visual>
      <origin
        xyz="0 0 0"
        rpy="0 0 0" />
      <geometry>
        <mesh
          filename="package://broom/meshes/broom_foot.STL" />
      </geometry>
      <material
        name="">
        <color
          rgba="0.79216 0.81961 0.93333 1" />
      </material>
    </visual>
    <collision>
      <origin
        xyz="0 0 0"
        rpy="0 0 0" />
      <geometry>
        <mesh
          filename="package://broom/meshes/broom_foot.STL" />
      </geometry>
    </collision>
  </link>
  <link
    name="broom_head">
    <inertial>
      <origin
        xyz="3.52E-17 -0.033742 3.9734E-18"
        rpy="0 0 0" />
      <mass
        value="0.15357" />
      <inertia
        ixx="3.7442E-05"
        ixy="-3.5226E-20"
        ixz="2.6418E-21"
        iyy="0.00078341"
        iyz="-1.8246E-21"
        izz="0.00081674" />
    </inertial>
    <visual>
      <origin
        xyz="0 0 0"
        rpy="0 0 0" />
      <geometry>
        <mesh
          filename="package://broom/meshes/broom_head.STL" />
      </geometry>
      <material
        name="">
        <color
          rgba="0.79216 0.81961 0.93333 1" />
      </material>
    </visual>
    <collision>
      <origin
        xyz="0 0 0"
        rpy="0 0 0" />
      <geometry>
        <mesh
          filename="package://broom/meshes/broom_head.STL" />
      </geometry>
    </collision>
  </link>
  <joint
    name="broom_joint"
    type="revolute">
    <origin
      xyz="0 0 -0.85"
      rpy="1.5708 0 0" />
    <parent
      link="broom_foot" />
    <child
      link="broom_head" />
    <axis
      xyz="0 0 1" />
    <limit
      lower="-0.785"
      upper="785"
      effort="0"
      velocity="0" />
    <calibration
      rising="0"
      falling="0" />
    <dynamics
      damping="0"
      friction="0.001" />
    <safety_controller
      soft_upper="0"
      soft_lower="0"
      k_position="0"
      k_velocity="0" />
  </joint>
</robot>