<robot
  name="broom">
  <link
    name="broom_foot">
    <inertial>
      <origin
        xyz="2.6394E-08 -0.43128 -2.2446E-08"
        rpy="0 0 0" />
      <mass
        value="0.3" />
      <inertia
        ixx="1"
        ixy="1"
        ixz="1"
        iyy="1"
        iyz="1"
        izz="1" />
    </inertial>
    <visual>
      <origin
        xyz="0 0 0"
        rpy="0 0 0" />
      <geometry>
        <mesh
          filename="package://broom/meshes/broom_foot.STL" />
      </geometry>
      <material
        name="">
        <color
          rgba="0.79216 0.81961 0.93333 1" />
      </material>
    </visual>
    <collision>
      <origin
        xyz="0 0 0"
        rpy="0 0 0" />
      <geometry>
        <mesh
          filename="package://broom/meshes/broom_foot.STL" />
      </geometry>
    </collision>
  </link>
  <link
    name="broom_head">
    <inertial>
      <origin
        xyz="3.52E-17 -0.033742 3.9734E-18"
        rpy="0 0 0" />
      <mass
        value="0.3" />
      <inertia
        ixx="1"
        ixy="1"
        ixz="1"
        iyy="1"
        iyz="1"
        izz="1" />
    </inertial>
    <visual>
      <origin
        xyz="0 0 0"
        rpy="0 0 0" />
      <geometry>
        <mesh
          filename="package://broom/meshes/broom_head.STL" />
      </geometry>
      <material
        name="">
        <color
          rgba="0.79216 0.81961 0.93333 1" />
      </material>
    </visual>
    <collision>
      <origin
        xyz="0 0 0"
        rpy="0 0 0" />
      <geometry>
        <mesh
          filename="package://broom/meshes/broom_head.STL" />
      </geometry>
    </collision>
  </link>
  <joint
    name="broom_joint"
    type="revolute">
    <origin
      xyz="0 0 -0.85"
      rpy="1.5708 0 0" />
    <parent
      link="broom_foot" />
    <child
      link="broom_head" />
    <axis
      xyz="0 0 1" />
    <limit
      lower="-0.785"
      upper="0.785"
      effort="0"
      velocity="0" />
    <calibration
      rising="0"
      falling="0" />
    <dynamics
      damping="0"
      friction="0.01" />
    <safety_controller
      soft_upper="0"
      soft_lower="0"
      k_position="0"
      k_velocity="0" />
  </joint>
</robot>
