<?xml version="1.0" encoding="utf-8"?>
<!-- =================================================================================== -->
<!-- |    This document was autogenerated by xacro from sia20_with_gripper.urdf.xacro  | -->
<!-- |    EDITING THIS FILE BY HAND IS NOT RECOMMENDED                                 | -->
<!-- =================================================================================== -->
<robot name="sia20" xmlns:xacro="http://www.ros.org/wiki/xacro">
  <!-- color of robot. important-->
  <material name="white">
    <color rgba="1 1 1 1"/>
  </material>
  <!-- base_link-->
  <link name="base_link">
    <inertial>
      <mass value="1.0"/>
      <origin rpy="0 0 0" xyz="0 0 0"/>
      <geometry>
        <mesh filename="package://sia20_description/meshes/base_link.STL"/>
      </geometry>
      <inertia ixx="0.001" ixy="0.001" ixz="0.001" iyy="0.001" iyz="0.001" izz="0.001"/>
    </inertial>
    <visual>
      <origin rpy="0 0 0" xyz="0 0 0"/>
      <geometry>
        <mesh filename="package://sia20_description/meshes/base_link.STL"/>
      </geometry>
      <material name="white"/>
    </visual>
    <collision>
      <origin rpy="0 0 0" xyz="0 0 0"/>
      <geometry>
        <mesh filename="package://sia20_description/meshes/base_link.STL"/>
      </geometry>
    </collision>
  </link>
  <!-- link_s-->
  <link name="link_s">
    <inertial>
      <mass value="1.0"/>
      <origin rpy="0 0 0" xyz="7.8023E-07 0.18911 -0.015611"/>
      <geometry>
        <mesh filename="package://sia20_description/meshes/link_s.STL"/>
      </geometry>
      <inertia ixx="0.001" ixy="0.001" ixz="0.001" iyy="0.001" iyz="0.001" izz="0.001"/>
    </inertial>
    <visual>
      <origin rpy="0 0 0" xyz="0 0 0"/>
      <geometry>
        <mesh filename="package://sia20_description/meshes/link_s.STL"/>
      </geometry>
      <material name="white"/>
    </visual>
    <collision>
      <origin rpy="0 0 0" xyz="0 0 0"/>
      <geometry>
        <mesh filename="package://sia20_description/meshes/link_s.STL"/>
      </geometry>
    </collision>
  </link>
  <!-- joint_s (base_link | joint_s) -->
  <joint name="joint_s" type="revolute">
    <origin rpy="1.5708 0 0" xyz="0 0 0.112"/>
    <parent link="base_link"/>
    <child link="link_s"/>
    <axis xyz="0 1 0"/>
    <limit effort="100" lower="-3.1415" upper="3.1415" velocity="2.2698"/>
    <!--
		<calibration rising="0" falling="0"/>
		<dynamics damping="0" fraction="0"/>
		<safety_controller soft_upper="0" soft_lower="0" k_position="0" k_velocity="0"/>
		-->
  </joint>
  <transmission name="joint_s_trans">
    <type>transimission_interface/SimpleTransmission</type>
    <joint name="joint_s">
      <hardwareInterface>hardware_interface/EffortJointInterface</hardwareInterface>
    </joint>
    <actuator name="joint_s_motor">
      <hardwareInterface>hardware_interface/EffortJointInterface</hardwareInterface>
      <mechanicalReduction>1</mechanicalReduction>
    </actuator>
  </transmission>
  <!-- link_l-->
  <link name="link_l">
    <inertial>
      <mass value="1.0"/>
      <origin rpy="0 0 0" xyz="1.6057E-05 0.10201 0.041335"/>
      <geometry>
        <mesh filename="package://sia20_description/meshes/link_l.STL"/>
      </geometry>
      <inertia ixx="0.001" ixy="0.001" ixz="0.001" iyy="0.001" iyz="0.001" izz="0.001"/>
    </inertial>
    <visual>
      <origin rpy="0 0 0" xyz="0 0 0"/>
      <geometry>
        <mesh filename="package://sia20_description/meshes/link_l.STL"/>
      </geometry>
      <material name="white"/>
    </visual>
    <collision>
      <origin rpy="0 0 0" xyz="0 0 0"/>
      <geometry>
        <mesh filename="package://sia20_description/meshes/link_l.STL"/>
      </geometry>
    </collision>
  </link>
  <!-- joint_l (link_s | joint_l) -->
  <joint name="joint_l" type="revolute">
    <origin rpy="0 0 0" xyz="0 0.298 0"/>
    <parent link="link_s"/>
    <child link="link_l"/>
    <axis xyz="0 0 1"/>
    <limit effort="100" lower="-1.9198" upper="1.9198" velocity="2.2698"/>
    <!--
		<calibration rising="0" falling="0"/>
		<dynamics damping="0" fraction="0"/>
		<safety_controller soft_upper="0" soft_lower="0" k_position="0" k_velocity="0"/>
		-->
  </joint>
  <transmission name="joint_l_trans">
    <type>transimission_interface/SimpleTransmission</type>
    <joint name="joint_l">
      <hardwareInterface>hardware_interface/EffortJointInterface</hardwareInterface>
    </joint>
    <actuator name="joint_l_motor">
      <hardwareInterface>hardware_interface/EffortJointInterface</hardwareInterface>
      <mechanicalReduction>1</mechanicalReduction>
    </actuator>
  </transmission>
  <!-- link_e-->
  <link name="link_e">
    <inertial>
      <mass value="1.0"/>
      <origin rpy="0 0 0" xyz="3.9186E-05 0.16471 0.020774"/>
      <geometry>
        <mesh filename="package://sia20_description/meshes/link_e.STL"/>
      </geometry>
      <inertia ixx="0.001" ixy="0.001" ixz="0.001" iyy="0.001" iyz="0.001" izz="0.001"/>
    </inertial>
    <visual>
      <origin rpy="0 0 0" xyz="0 0 0"/>
      <geometry>
        <mesh filename="package://sia20_description/meshes/link_e.STL"/>
      </geometry>
      <material name="white"/>
    </visual>
    <collision>
      <origin rpy="0 0 0" xyz="0 0 0"/>
      <geometry>
        <mesh filename="package://sia20_description/meshes/link_e.STL"/>
      </geometry>
    </collision>
  </link>
  <!-- joint_e (link_l | joint_e) -->
  <joint name="joint_e" type="revolute">
    <origin rpy="0 0 0" xyz="0 0.247135547651375 0"/>
    <parent link="link_l"/>
    <child link="link_e"/>
    <axis xyz="0 1 0"/>
    <limit effort="100" lower="-2.967" upper="2.967" velocity="2.2698"/>
    <!--
		<calibration rising="0" falling="0"/>
		<dynamics damping="0" fraction="0"/>
		<safety_controller soft_upper="0" soft_lower="0" k_position="0" k_velocity="0"/>
		-->
  </joint>
  <transmission name="joint_e_trans">
    <type>transimission_interface/SimpleTransmission</type>
    <joint name="joint_e">
      <hardwareInterface>hardware_interface/EffortJointInterface</hardwareInterface>
    </joint>
    <actuator name="joint_e_motor">
      <hardwareInterface>hardware_interface/EffortJointInterface</hardwareInterface>
      <mechanicalReduction>1</mechanicalReduction>
    </actuator>
  </transmission>
  <!-- link_u-->
  <link name="link_u">
    <inertial>
      <mass value="1.0"/>
      <origin rpy="0 0 0" xyz="-7.9992E-07 0.08472 -0.032542"/>
      <geometry>
        <mesh filename="package://sia20_description/meshes/link_u.STL"/>
      </geometry>
      <inertia ixx="0.001" ixy="0.001" ixz="0.001" iyy="0.001" iyz="0.001" izz="0.001"/>
    </inertial>
    <visual>
      <origin rpy="0 0 0" xyz="0 0 0"/>
      <geometry>
        <mesh filename="package://sia20_description/meshes/link_u.STL"/>
      </geometry>
      <material name="white"/>
    </visual>
    <collision>
      <origin rpy="0 0 0" xyz="0 0 0"/>
      <geometry>
        <mesh filename="package://sia20_description/meshes/link_u.STL"/>
      </geometry>
    </collision>
  </link>
  <!-- joint_u (link_e | joint_u) -->
  <joint name="joint_u" type="revolute">
    <origin rpy="0 0 0" xyz="0 0.242864452348634 0"/>
    <parent link="link_e"/>
    <child link="link_u"/>
    <axis xyz="0 0 1"/>
    <limit effort="100" lower="-2.967" upper="2.967" velocity="2.2698"/>
    <!--
		<calibration rising="0" falling="0"/>
		<dynamics damping="0" fraction="0"/>
		<safety_controller soft_upper="0" soft_lower="0" k_position="0" k_velocity="0"/>
		-->
  </joint>
  <transmission name="joint_u_trans">
    <type>transimission_interface/SimpleTransmission</type>
    <joint name="joint_u">
      <hardwareInterface>hardware_interface/EffortJointInterface</hardwareInterface>
    </joint>
    <actuator name="joint_u_motor">
      <hardwareInterface>hardware_interface/EffortJointInterface</hardwareInterface>
      <mechanicalReduction>1</mechanicalReduction>
    </actuator>
  </transmission>
  <!-- link_r-->
  <link name="link_r">
    <inertial>
      <mass value="1.0"/>
      <origin rpy="0 0 0" xyz="4.8678E-06 0.12569 -0.02028"/>
      <geometry>
        <mesh filename="package://sia20_description/meshes/link_r.STL"/>
      </geometry>
      <inertia ixx="0.001" ixy="0.001" ixz="0.001" iyy="0.001" iyz="0.001" izz="0.001"/>
    </inertial>
    <visual>
      <origin rpy="0 0 0" xyz="0 0 0"/>
      <geometry>
        <mesh filename="package://sia20_description/meshes/link_r.STL"/>
      </geometry>
      <material name="white"/>
    </visual>
    <collision>
      <origin rpy="0 0 0" xyz="0 0 0"/>
      <geometry>
        <mesh filename="package://sia20_description/meshes/link_r.STL"/>
      </geometry>
    </collision>
  </link>
  <!-- joint_r (link_u | joint_r) -->
  <joint name="joint_r" type="revolute">
    <origin rpy="0 0 0" xyz="0 0.23899999999989 0"/>
    <parent link="link_u"/>
    <child link="link_r"/>
    <axis xyz="0 1 0"/>
    <limit effort="100" lower="-3.1415" upper="3.1415" velocity="3.4906"/>
    <!--
		<calibration rising="0" falling="0"/>
		<dynamics damping="0" fraction="0"/>
		<safety_controller soft_upper="0" soft_lower="0" k_position="0" k_velocity="0"/>
		-->
  </joint>
  <transmission name="joint_r_trans">
    <type>transimission_interface/SimpleTransmission</type>
    <joint name="joint_r">
      <hardwareInterface>hardware_interface/EffortJointInterface</hardwareInterface>
    </joint>
    <actuator name="joint_r_motor">
      <hardwareInterface>hardware_interface/EffortJointInterface</hardwareInterface>
      <mechanicalReduction>1</mechanicalReduction>
    </actuator>
  </transmission>
  <!-- link_b-->
  <link name="link_b">
    <inertial>
      <mass value="1.0"/>
      <origin rpy="0 0 0" xyz="5.1667E-06 0.069849 0.019496"/>
      <geometry>
        <mesh filename="package://sia20_description/meshes/link_b.STL"/>
      </geometry>
      <inertia ixx="0.001" ixy="0.001" ixz="0.001" iyy="0.001" iyz="0.001" izz="0.001"/>
    </inertial>
    <visual>
      <origin rpy="0 0 0" xyz="0 0 0"/>
      <geometry>
        <mesh filename="package://sia20_description/meshes/link_b.STL"/>
      </geometry>
      <material name="white"/>
    </visual>
    <collision>
      <origin rpy="0 0 0" xyz="0 0 0"/>
      <geometry>
        <mesh filename="package://sia20_description/meshes/link_b.STL"/>
      </geometry>
    </collision>
  </link>
  <!-- joint_b (link_r | joint_b) -->
  <joint name="joint_b" type="revolute">
    <origin rpy="0 0 0" xyz="0 0.181 0"/>
    <parent link="link_r"/>
    <child link="link_b"/>
    <axis xyz="0 0 1"/>
    <limit effort="100" lower="-1.9198" upper="1.9198" velocity="3.4906"/>
    <!--
		<calibration rising="0" falling="0"/>
		<dynamics damping="0" fraction="0"/>
		<safety_controller soft_upper="0" soft_lower="0" k_position="0" k_velocity="0"/>
		-->
  </joint>
  <transmission name="joint_b_trans">
    <type>transimission_interface/SimpleTransmission</type>
    <joint name="joint_b">
      <hardwareInterface>hardware_interface/EffortJointInterface</hardwareInterface>
    </joint>
    <actuator name="joint_b_motor">
      <hardwareInterface>hardware_interface/EffortJointInterface</hardwareInterface>
      <mechanicalReduction>1</mechanicalReduction>
    </actuator>
  </transmission>
  <!-- link_t-->
  <link name="link_t">
    <inertial>
      <mass value="1.0"/>
      <origin rpy="0 0 0" xyz="-0.00019051 0.0087466 -2.475E-05"/>
      <geometry>
        <mesh filename="package://sia20_description/meshes/link_t.STL"/>
      </geometry>
      <inertia ixx="0.001" ixy="0.001" ixz="0.001" iyy="0.001" iyz="0.001" izz="0.001"/>
    </inertial>
    <visual>
      <origin rpy="0 0 0" xyz="0 0 0"/>
      <geometry>
        <mesh filename="package://sia20_description/meshes/link_t.STL"/>
      </geometry>
      <material name="white"/>
    </visual>
    <collision>
      <origin rpy="0 0 0" xyz="0 0 0"/>
      <geometry>
        <mesh filename="package://sia20_description/meshes/link_t.STL"/>
      </geometry>
    </collision>
  </link>
  <!-- joint_t (link_b | joint_t) -->
  <joint name="joint_t" type="revolute">
    <origin rpy="0 0 0" xyz="0 0.164069662461231 0.0015"/>
    <parent link="link_b"/>
    <child link="link_t"/>
    <axis xyz="0 1 0"/>
    <limit effort="100" lower="-3.1415" upper="3.1415" velocity="7.0"/>
    <!--
		<calibration rising="0" falling="0"/>
		<dynamics damping="0" fraction="0"/>
		<safety_controller soft_upper="0" soft_lower="0" k_position="0" k_velocity="0"/>
		-->
  </joint>
  <transmission name="joint_t_trans">
    <type>transimission_interface/SimpleTransmission</type>
    <joint name="joint_t">
      <hardwareInterface>hardware_interface/EffortJointInterface</hardwareInterface>
    </joint>
    <actuator name="joint_t_motor">
      <hardwareInterface>hardware_interface/EffortJointInterface</hardwareInterface>
      <mechanicalReduction>1</mechanicalReduction>
    </actuator>
  </transmission>
  <!-- link tool0-->
  <link name="tool0"/>
  <!-- joint link_t-tool0 -->
  <joint name="link_t-tool0" type="fixed">
    <origin rpy="0 0 -3.1415" xyz="0 0 0"/>
    <parent link="link_t"/>
    <child link="tool0"/>
  </joint>
  <!-- link fixed in order to stand rigidly in gazebo -->
  <link name="world"/>
  <joint name="fixed" type="fixed">
    <parent link="world"/>
    <child link="base_link"/>
  </joint>
  <!-- ros_control_plugin-->
  <gazebo>
    <plugin filename="libgazebo_ros_control.so" name="gazebo_ros_control">
      <robotNamespace>/sia20</robotNamespace>
    </plugin>
    <mu1>0.1</mu1>
    <mu2>0.1</mu2>
  </gazebo>
  <!-- include common macro file-->
  <!--xacro:include filename="common.urdf.xacro" /-->
  <link name="left_gripper">
    <collision>
      <origin rpy="0 0 -1.5708" xyz="0.013 -0.02 0"/>
      <geometry>
        <mesh filename="package://urdf_tutorial/meshes/l_finger.dae"/>
      </geometry>
    </collision>
    <inertial>
      <mass value="0.01"/>
      <inertia ixx="0.1" ixy="0.1" ixz="0.1" iyy="0.1" iyz="0.1" izz="0.1"/>
    </inertial>
    <visual>
      <origin rpy="0 0 -1.5708" xyz="0.013 -0.02 0"/>
      <geometry>
        <mesh filename="package://urdf_tutorial/meshes/l_finger.dae"/>
      </geometry>
    </visual>
  </link>
  <link name="left_tip">
    <visual>
      <origin rpy="0 0 0" xyz="0.09137 0.00495 0"/>
      <geometry>
        <mesh filename="package://urdf_tutorial/meshes/l_finger_tip.dae"/>
      </geometry>
    </visual>
    <collision>
      <geometry>
        <mesh filename="package://urdf_tutorial/meshes/l_finger_tip.dae"/>
      </geometry>
      <origin rpy="0 0 0" xyz="0.09137 0.00495 0"/>
    </collision>
    <inertial>
      <mass value="0.01"/>
      <inertia ixx="0.1" ixy="0.1" ixz="0.1" iyy="0.1" iyz="0.1" izz="0.1"/>
    </inertial>
  </link>
  <joint name="left_tip_joint" type="fixed">
    <parent link="left_gripper"/>
    <child link="left_tip"/>
  </joint>
  <link name="right_gripper">
    <visual>
      <origin rpy="3.14 0 -1.5708" xyz="-0.013 -0.02 0"/>
      <geometry>
        <mesh filename="package://urdf_tutorial/meshes/l_finger.dae"/>
      </geometry>
    </visual>
    <collision>
      <geometry>
        <mesh filename="package://urdf_tutorial/meshes/l_finger.dae"/>
      </geometry>
      <origin rpy="3.14 0 -1.5708" xyz="-0.013 -0.02 0"/>
    </collision>
    <inertial>
      <mass value="0.01"/>
      <inertia ixx="0.1" ixy="0.1" ixz="0.1" iyy="0.1" iyz="0.1" izz="0.1"/>
    </inertial>
  </link>
  <link name="right_tip">
    <visual>
      <origin rpy="3.14 0 0" xyz="0.09137 0.00495 0"/>
      <geometry>
        <mesh filename="package://urdf_tutorial/meshes/l_finger_tip.dae"/>
      </geometry>
    </visual>
    <collision>
      <geometry>
        <mesh filename="package://urdf_tutorial/meshes/l_finger_tip.dae"/>
      </geometry>
      <origin rpy="3.14 0 0" xyz="0.09137 0.00495 0"/>
    </collision>
    <inertial>
      <mass value="0.01"/>
      <inertia ixx="0.1" ixy="0.1" ixz="0.1" iyy="0.1" iyz="0.1" izz="0.1"/>
    </inertial>
  </link>
  <joint name="right_tip_joint" type="fixed">
    <parent link="right_gripper"/>
    <child link="right_tip"/>
  </joint>
  <!-- concatenate gripper to robot -->
  <joint name="wrist_to_l" type="revolute">
    <parent link="link_t"/>
    <child link="left_gripper"/>
    <limit effort="1000" lower="-0.07" upper="0.548" velocity="3"/>
    <axis xyz="0 0 1"/>
  </joint>
  <joint name="wrist_to_r" type="revolute">
    <parent link="link_t"/>
    <child link="right_gripper"/>
    <limit effort="1000" lower="-0.07" upper="0.548" velocity="3"/>
    <axis xyz="0 0 -1"/>
  </joint>
  <!-- transmission -->
  <!-- left gripper -->
  <transmission name="left_gripper_trans">
    <type>transmission_interface/SimpleTransmission</type>
    <joint name="wrist_to_l">
      <hardwareInterface>hardware_interface/EffortJointInterface</hardwareInterface>
    </joint>
    <actuator name="wrist_to_l_motor">
      <hardwareInterface>hardware_interface/EffortJointInterface</hardwareInterface>
      <mechanicalReduction>1</mechanicalReduction>
    </actuator>
  </transmission>
  <!-- right gripper -->
  <transmission name="right_gripper_trans">
    <type>transmission_interface/SimpleTransmission</type>
    <joint name="wrist_to_r">
      <hardwareInterface>hardware_interface/EffortJointInterface</hardwareInterface>
    </joint>
    <actuator name="wrist_to_r_motor">
      <hardwareInterface>hardware_interface/EffortJointInterface</hardwareInterface>
      <mechanicalReduction>1</mechanicalReduction>
    </actuator>
  </transmission>
</robot>

