<?xml version="1.0"?>
<robot name="sia20" xmlns:xacro="http://www.ros.org/wiki/xacro">

	<!-- include macro file-->
	<xacro:include filename="common.urdf.xacro"/>

	<!-- base_link-->
	<link name="base_link">
		<inertial>
			<mass value="1.0"/>
			<!--xacro:inertia_origin_base_link/-->
			<xacro:default_origin/>
			<xacro:default_mesh name="base_link"/>
			<xacro:default_inertial/>
		</inertial>
		<visual>
			<xacro:default_origin/>
			<xacro:default_mesh name="base_link"/>
			<material name="white"/>
		</visual>
		<collision>
			<xacro:default_origin/>
			<xacro:default_mesh name="base_link"/>
		</collision>
	</link>

	<!-- link_s-->
	<link name="link_s">
		<inertial>
			<mass value="1.0"/>
			<xacro:inertia_origin_link_s/>
			<xacro:default_mesh name="link_s"/>
			<xacro:default_inertial/>
		</inertial>
		<visual>
			<xacro:default_origin/>
			<xacro:default_mesh name="link_s"/>
			<material name="white"/>
		</visual>
		<collision>
			<xacro:default_origin/>
			<xacro:default_mesh name="link_s"/>
		</collision>
	</link>

	<!-- joint_s (base_link | joint_s) -->
	<joint name="joint_s" type="revolute">
		<xacro:origin_joint_s/>
		<parent link="base_link"/>
		<child  link="link_s"/>
		<axis xyz="0 1 0"/>
		<limit lower="-3.1415" upper="3.1415" effort="1000" velocity="2.2698"/>
		<xacro:default_joint_misc/>
	</joint>
	<xacro:default_transmission suffix="joint_s"/>


	<!-- link_l-->
	<link name="link_l">
		<inertial>
			<mass value="1.0"/>
			<xacro:inertia_origin_link_l/>
			<xacro:default_mesh name="link_l"/>
			<xacro:default_inertial/>
		</inertial>
		<visual>
			<xacro:default_origin/>
			<xacro:default_mesh name="link_l"/>
			<material name="white"/>
		</visual>
		<collision>
			<xacro:default_origin/>
			<xacro:default_mesh name="link_l"/>
		</collision>
	</link>

	<!-- joint_l (link_s | joint_l) -->
	<joint name="joint_l" type="revolute">
		<xacro:origin_joint_l/>
		<parent link="link_s"/>
		<child  link="link_l"/>
		<axis xyz="0 0 1"/>
		<limit lower="-1.9198" upper="1.9198" effort="1000" velocity="2.2698"/>
		<xacro:default_joint_misc/>
	</joint>
	<xacro:default_transmission suffix="joint_l"/>

	<!-- link_e-->
	<link name="link_e">
		<inertial>
			<mass value="1.0"/>
			<xacro:inertia_origin_link_e/>
			<xacro:default_mesh name="link_e"/>
			<xacro:default_inertial/>
		</inertial>
		<visual>
			<xacro:default_origin/>
			<xacro:default_mesh name="link_e"/>
			<material name="white"/>
		</visual>
		<collision>
			<xacro:default_origin/>
			<xacro:default_mesh name="link_e"/>
		</collision>
	</link>

	<!-- joint_e (link_l | joint_e) -->
	<joint name="joint_e" type="revolute">
		<xacro:origin_joint_e/>
		<parent link="link_l"/>
		<child  link="link_e"/>
		<axis xyz="0 1 0"/>
		<limit lower="-2.967" upper="2.967" effort="1000" velocity="2.2698"/>
		<xacro:default_joint_misc/>
	</joint>
	<xacro:default_transmission suffix="joint_e"/>

	<!-- link_u-->
	<link name="link_u">
		<inertial>
			<mass value="1.0"/>
			<xacro:inertia_origin_link_u/>
			<xacro:default_mesh name="link_u"/>
			<xacro:default_inertial/>
		</inertial>
		<visual>
			<xacro:default_origin/>
			<xacro:default_mesh name="link_u"/>
			<material name="white"/>
		</visual>
		<collision>
			<xacro:default_origin/>
			<xacro:default_mesh name="link_u"/>
		</collision>
	</link>

	<!-- joint_u (link_e | joint_u) -->
	<joint name="joint_u" type="revolute">
		<xacro:origin_joint_u/>
		<parent link="link_e"/>
		<child  link="link_u"/>
		<axis xyz="0 0 1"/>
		<limit lower="-2.967" upper="2.967" effort="1000" velocity="2.2698"/>
		<xacro:default_joint_misc/>
	</joint>
	<xacro:default_transmission suffix="joint_u"/>

	<!-- link_r-->
	<link name="link_r">
		<inertial>
			<mass value="1.0"/>
			<xacro:inertia_origin_link_r/>
			<xacro:default_mesh name="link_r"/>
			<xacro:default_inertial/>
		</inertial>
		<visual>
			<xacro:default_origin/>
			<xacro:default_mesh name="link_r"/>
			<material name="white"/>
		</visual>
		<collision>
			<xacro:default_origin/>
			<xacro:default_mesh name="link_r"/>
		</collision>
	</link>

	<!-- joint_r (link_u | joint_r) -->
	<joint name="joint_r" type="revolute">
		<xacro:origin_joint_r/>
		<parent link="link_u"/>
		<child  link="link_r"/>
		<axis xyz="0 1 0"/>
		<limit lower="-3.1415" upper="3.1415" effort="1000" velocity="3.4906"/>
		<xacro:default_joint_misc/>
	</joint>
	<xacro:default_transmission suffix="joint_r"/>

	<!-- link_b-->
	<link name="link_b">
		<inertial>
			<mass value="1.0"/>
			<xacro:inertia_origin_link_b/>
			<xacro:default_mesh name="link_b"/>
			<xacro:default_inertial/>
		</inertial>
		<visual>
			<xacro:default_origin/>
			<xacro:default_mesh name="link_b"/>
			<material name="white"/>
		</visual>
		<collision>
			<xacro:default_origin/>
			<xacro:default_mesh name="link_b"/>
		</collision>
	</link>

	<!-- joint_b (link_r | joint_b) -->
	<joint name="joint_b" type="revolute">
		<xacro:origin_joint_b/>
		<parent link="link_r"/>
		<child  link="link_b"/>
		<axis xyz="0 0 1"/>
		<limit lower="-1.9198" upper="1.9198" effort="1000" velocity="3.4906"/>
		<xacro:default_joint_misc/>
	</joint>
	<xacro:default_transmission suffix="joint_b"/>

	<!-- link_t-->
	<link name="link_t">
		<inertial>
			<mass value="1.0"/>
			<xacro:inertia_origin_link_t/>
			<xacro:default_mesh name="link_t"/>
			<xacro:default_inertial/>
		</inertial>
		<visual>
			<xacro:default_origin/>
			<xacro:default_mesh name="link_t"/>
			<material name="white"/>
		</visual>
		<collision>
			<xacro:default_origin/>
			<xacro:default_mesh name="link_t"/>
		</collision>
	</link>

	<!-- joint_t (link_b | joint_t) -->
	<joint name="joint_t" type="revolute">
		<xacro:origin_joint_t/>
		<parent link="link_b"/>
		<child  link="link_t"/>
		<axis xyz="0 1 0"/>
		<limit lower="-3.1415" upper="3.1415" effort="1000" velocity="7.0"/>
		<xacro:default_joint_misc/>
	</joint>
	<xacro:default_transmission suffix="joint_t"/>

	<!-- link tool0-->
	<link name="tool0"/>

	<!-- joint link_t-tool0 -->
	<joint name="link_t-tool0" type="fixed">
		<origin rpy="0 0 -3.1415" xyz="0 0 0"/>
		<parent link="link_t"/>
		<child  link="tool0"/>
	</joint>

	<!-- link fixed in order to stand rigidly in gazebo -->
	<link name="world"/>
	<joint name="fixed" type="fixed">
		<parent link="world"/>
		<child  link="base_link"/>
	</joint>

	<!-- ros_control_plugin-->
	<gazebo>
		<plugin name="gazebo_ros_control" filename="libgazebo_ros_control.so">
			<robotNamespace>/sia20</robotNamespace>
		</plugin>
		<mu1>0.1</mu1>
		<mu2>0.1</mu2>
	</gazebo>

</robot>
