<?xml version="1.0"?>
<robot name="sia20f">
  <link name="base_link">
    <inertial>
      <origin xyz="-0.05327 0.066798 0.00014271" rpy="0 0 0" />
      <mass value="9.5604" />
      <inertia
        ixx="0"
        ixy="0"
        ixz="0"
        iyy="0"
        iyz="0"
        izz="0" />
    </inertial>
    <visual>
      <origin xyz="0 0 0" rpy="0 0 0" />
      <geometry>
        <mesh filename="package://sia20f/meshes/base_link.STL" />
      </geometry>
      <material name="">
        <color rgba="1 1 1 1" />
      </material>
    </visual>
    <collision>
      <origin xyz="0 0 0" rpy="0 0 0" />
      <geometry>
        <mesh filename="package://sia20f/meshes/base_link.STL" />
      </geometry>
    </collision>
  </link>
  <link name="link_s">
    <inertial>
      <origin xyz="7.8023E-07 0.18911 -0.015611" rpy="0 0 0" />
      <mass value="11.757" />
      <inertia
        ixx="0"
        ixy="0"
        ixz="0"
        iyy="0"
        iyz="0"
        izz="0" />
    </inertial>
    <visual>
      <origin xyz="0 0 0" rpy="0 0 0" />
      <geometry>
        <mesh
          filename="package://sia20f/meshes/link_s.STL" />
      </geometry>
      <material name="">
        <color rgba="1 1 1 1" />
      </material>
    </visual>
    <collision>
      <origin xyz="0 0 0" rpy="0 0 0" />
      <geometry>
        <mesh filename="package://sia20f/meshes/link_s.STL" />
      </geometry>
    </collision>
  </link>
  <joint name="joint_s" type="revolute">
    <origin xyz="0 0 0.112" rpy="1.5708 0 0" />
    <parent link="base_link" />
    <child link="link_s" />
    <axis xyz="0 1 0" />
    <limit lower="-3.1415" upper="3.1415" effort="100" velocity="2.2689" />
    <calibration rising="0" falling="0" />
    <dynamics damping="0" friction="0" />
    <safety_controller soft_upper="0" soft_lower="0" k_position="0" k_velocity="0" />
  </joint>
  <link name="link_l">
    <inertial>
      <origin xyz="1.6057E-05 0.10201 0.041335" rpy="0 0 0" />
      <mass value="6.5581" />
      <inertia
        ixx="0"
        ixy="0"
        ixz="0"
        iyy="0"
        iyz="0"
        izz="0" />
    </inertial>
    <visual>
      <origin xyz="0 0 0" rpy="0 0 0" />
      <geometry>
        <mesh filename="package://sia20f/meshes/link_l.STL" />
      </geometry>
      <material name="">
        <color rgba="1 1 1 1" />
      </material>
    </visual>
    <collision>
      <origin xyz="0 0 0" rpy="0 0 0" />
      <geometry>
        <mesh filename="package://sia20f/meshes/link_l.STL" />
      </geometry>
    </collision>
  </link>
  <joint name="joint_l"
    type="revolute">
    <origin xyz="0 0.298 0" rpy="0 0 0" />
    <parent link="link_s" />
    <child link="link_l" />
    <axis xyz="0 0 1" />
    <limit lower="-1.9198" upper="1.9198" effort="100" velocity="2.2689" />
    <calibration rising="0" falling="0" />
    <dynamics damping="0" friction="0" />
    <safety_controller soft_upper="0" soft_lower="0" k_position="0" k_velocity="0" />
  </joint>
  <link
    name="link_e">
    <inertial>
      <origin xyz="3.9186E-05 0.16471 0.020774" rpy="0 0 0" />
      <mass value="6.2419" />
      <inertia
        ixx="0"
        ixy="0"
        ixz="0"
        iyy="0"
        iyz="0"
        izz="0" />
    </inertial>
    <visual>
      <origin xyz="0 0 0" rpy="0 0 0" />
      <geometry>
        <mesh filename="package://sia20f/meshes/link_e.STL" />
      </geometry>
      <material name="">
        <color rgba="1 1 1 1" />
      </material>
    </visual>
    <collision>
      <origin xyz="0 0 0" rpy="0 0 0" />
      <geometry>
        <mesh filename="package://sia20f/meshes/link_e.STL" />
      </geometry>
    </collision>
  </link>
  <joint
    name="joint_e"
    type="revolute">
    <origin xyz="0 0.247135547651375 0" rpy="0 0 0" />
    <parent link="link_l" />
    <child link="link_e" />
    <axis xyz="0 1 0" />
    <limit lower="-2.9670" upper="2.9670" effort="100" velocity="2.9670" />
    <calibration rising="0" falling="0" />
    <dynamics damping="0" friction="0" />
    <safety_controller soft_upper="0" soft_lower="0" k_position="0" k_velocity="0" />
  </joint>
  <link name="link_u">
    <inertial>
      <origin xyz="-7.9992E-07 0.08472 -0.032542" rpy="0 0 0" />
      <mass value="4.4611" />
      <inertia
        ixx="0"
        ixy="0"
        ixz="0"
        iyy="0"
        iyz="0"
        izz="0" />
    </inertial>
    <visual>
      <origin xyz="0 0 0" rpy="0 0 0" />
      <geometry>
        <mesh filename="package://sia20f/meshes/link_u.STL" />
      </geometry>
      <material name="">
        <color rgba="1 1 1 1" />
      </material>
    </visual>
    <collision>
      <origin xyz="0 0 0" rpy="0 0 0" />
      <geometry>
        <mesh filename="package://sia20f/meshes/link_u.STL" />
      </geometry>
    </collision>
  </link>
  <joint name="joint_u" type="revolute">
    <origin xyz="0 0.242864452348634 0" rpy="0 0 0" />
    <parent link="link_e" />
    <child link="link_u" />
    <axis xyz="0 0 1" />
    <limit lower="-2.9670" upper="2.9670" effort="100" velocity="2.9670" />
    <calibration rising="0" falling="0" />
    <dynamics damping="0" friction="0" />
    <safety_controller soft_upper="0" soft_lower="0" k_position="0" k_velocity="0" />
  </joint>
  <link
    name="link_r">
    <inertial>
      <origin xyz="4.8678E-06 0.12569 -0.02028" rpy="0 0 0" />
      <mass value="2.4173" />
      <inertia
        ixx="0"
        ixy="0"
        ixz="0"
        iyy="0"
        iyz="0"
        izz="0" />
    </inertial>
    <visual>
      <origin xyz="0 0 0" rpy="0 0 0" />
      <geometry>
        <mesh filename="package://sia20f/meshes/link_r.STL" />
      </geometry>
      <material name="">
        <color rgba="1 1 1 1" />
      </material>
    </visual>
    <collision>
      <origin xyz="0 0 0" rpy="0 0 0" />
      <geometry>
        <mesh filename="package://sia20f/meshes/link_r.STL" />
      </geometry>
    </collision>
  </link>
  <joint name="joint_r" type="revolute">
    <origin xyz="0 0.23899999999989 0" rpy="0 0 0" />
    <parent link="link_u" />
    <child link="link_r" />
    <axis xyz="0 1 0" />
    <limit lower="-3.1415" upper="3.1414" effort="100" velocity="3.4906" />
    <calibration rising="0" falling="0" />
    <dynamics damping="0" friction="0" />
    <safety_controller soft_upper="0" soft_lower="0" k_position="0" k_velocity="0" />
  </joint>
  <link name="link_b">
    <inertial>
      <origin xyz="5.1667E-06 0.069849 0.019496" rpy="0 0 0" />
      <mass value="2.0184" />
      <inertia
        ixx="0"
        ixy="0"
        ixz="0"
        iyy="0"
        iyz="0"
        izz="0" />
    </inertial>
    <visual>
      <origin xyz="0 0 0" rpy="0 0 0" />
      <geometry>
        <mesh filename="package://sia20f/meshes/link_b.STL" />
      </geometry>
      <material name="">
        <color rgba="1 1 1 1" />
      </material>
    </visual>
    <collision>
      <origin xyz="0 0 0" rpy="0 0 0" />
      <geometry>
        <mesh filename="package://sia20f/meshes/link_b.STL" />
      </geometry>
    </collision>
  </link>
  <joint name="joint_b" type="continuous">
    <origin xyz="0 0.181 0" rpy="0 0 0" />
    <parent link="link_r" />
    <child link="link_b" />
    <axis xyz="0 0 1" />
    <limit lower="-1.9198" upper="1.9198" effort="100" velocity="3.4906" />
    <calibration rising="0" falling="0" />
    <dynamics damping="0" friction="0" />
    <safety_controller soft_upper="0" soft_lower="0" k_position="0" k_velocity="0" />
  </joint>
  <link name="link_t">
    <inertial>
      <origin xyz="-0.00019051 0.0087466 -2.475E-05" rpy="0 0 0" />
      <mass value="0.095976" />
      <inertia
        ixx="0"
        ixy="0"
        ixz="0"
        iyy="0"
        iyz="0"
        izz="0" />
    </inertial>
    <visual>
      <origin xyz="0 0 0" rpy="0 0 0" />
      <geometry>
        <mesh filename="package://sia20f/meshes/link_t.STL" />
      </geometry>
      <material name="">
        <color rgba="0.64706 0.61961 0.58824 1" />
      </material>
    </visual>
    <collision>
      <origin xyz="0 0 0" rpy="0 0 0" />
      <geometry>
        <mesh filename="package://sia20f/meshes/link_t.STL" />
      </geometry>
    </collision>
  </link>
  <joint name="joint_t" type="revolute">
    <origin xyz="0 0.164069662461231 0.0015" rpy="0 0 0" />
    <parent link="link_b" />
    <child link="link_t" />
    <axis xyz="0 1 0" />
    <limit lower="-3.14159" upper="3.14159" effort="100" velocity="7" />
    <calibration rising="0" falling="0" />
    <dynamics damping="0" friction="0" />
    <safety_controller soft_upper="0" soft_lower="0" k_position="0" k_velocity="0" />
  </joint>
</robot>
